Workbook

Sheet Organograma
A1: Nº diretoria | B1: Diretoria | C1: Nº da Gerência | D1: GERÊNCIA OU COORDENAÇÃO | E1: Responsavel pela gerência ou coordenação | F1: Nº do setor | G1: SETOR | H1: Responsável pelo Setor
A2: 1.1 | B2: Diretoria Geral | C2: 0 | D2: Ligado direto a diretoria | E2: Mylena Justino da Silva Brito | F2: 1.1.1 | G2: APGQ - Assessoria de Planejamento e Gestão da Qualidade | H2: Mylena Justino da Silva Brito
A3: 1.1 | B3: Diretoria Geral | C3: 0 | D3: Ligado direto a diretoria | E3: Rita De Cassia Rotterdan Lisboa | F3: 1.1.10 | G3: AC - Assessoria de Comunicação | H3: Rita De Cassia Rotterdan Lisboa
A4: 1.1 | B4: Diretoria Geral | C4: 0 | D4: Ligado direto a diretoria | E4: Cintia Kelciane Gomes de Oliveira | F4: 1.1.3 | G4: CEP - Centro de Ensino e Pesquisa | H4: Cintia Kelciane Gomes de Oliveira
A5: 1.1 | B5: Diretoria Geral | C5: 0 | D5: Ligado direto a diretoria | E5: Yuri Amorim Braga | F5: 1.1.5 | G5: Diretoria Geral | H5: Yuri Amorim Braga
A6: 1.1 | B6: Diretoria Geral | C6: 0 | D6: Ligado direto a diretoria | E6: Yuri Amorim Braga | F6: 1.1.6 | G6: Assessoria da Diretoria Geral | H6: Natacha Flora Alves de Moraes
A7: 1.1 | B7: Diretoria Geral | C7: 0 | D7: Ligado direto a diretoria | E7: Rafaela Braga Simões | F7: 1.1.6 | G7: NGAH - Núcleo de Gestão de Atendimento e Humanização | H7: Rafaela Braga Simões
A8: 1.1 | B8: Diretoria Geral | C8: 0 | D8: Ligado direto a diretoria | E8: Mylena Justino da Silva Brito | F8: 1.1.7 | G8: NSP - Núcleo de Segurança do Paciente | H8: Mylena Justino da Silva Brito
A9: 1.1 | B9: Diretoria Geral | C9: 0 | D9: Ligado direto a diretoria | E9: Regia Carla da Silva Conceicao | F9: 1.1.8 | G9: OUV - Ouvidoria | H9: Regia Carla da Silva Conceicao
A10: 1.1 | B10: Diretoria Geral | C10: 0 | D10: Ligado direto a diretoria | E10: Andrew Silva de Lima | F10: 1.1.9 | G10: TI - Serviço de Tecnologia de Informação | H10: Andrew Silva de Lima
A11: 2.1 | B11: Diretoria Técnica | C11: 2.1.34 | D11: Gerência Ambulatorial e do Apoio Diagnóstico | E11: Camila Amanda Cardoso dos Santos | F11: 2.1.34.1 | G11: AMB - Unidade Ambulatorial | H11: Camila Amanda Cardoso dos Santos
A12: 2.1 | B12: Diretoria Técnica | C12: 2.1.34 | D12: Gerência Ambulatorial e do Apoio Diagnóstico | E12: Camila Amanda Cardoso dos Santos | F12: 2.1.34.5 | G12: AT - Agência Transfusional | H12: Camila Amanda Cardoso dos Santos
A13: 2.1 | B13: Diretoria Técnica | C13: 2.1.33 | D13: Gerência de Cuidado Materno/Infantil | E13: Camila Nascimento Santos Santana | F13: 2.1.33.1 | G13: BLH - Banco de Leite Humano | H13: Flavia de Souza Moura
A14: 2.1 | B14: Diretoria Técnica | C14: 2.1.8 | D14: Coordenação de Internação | E14: Janaina Bernardes Ayer | F14: 2.1.8.8 | G14: CA - Controle de Acesso | H14: Janaina Bernardes Ayer
A15: 2.1 | B15: Diretoria Técnica | C15: 2.1.35 | D15: Gerência de Cuidados Cirúrgicos | E15: Evila Ellen Sa De Moraes Matias | F15: 2.1.35.1 | G15: CC - Centro Cirúrgico | H15: Evila Ellen Sa De Moraes Matias
A16: 2.1 | B16: Diretoria Técnica | C16: 2.1.33 | D16: Gerência de Cuidado Materno/Infantil | E16: Camila Nascimento Santos Santana | F16: 2.1.33.2 | G16: CGO - Unidade de Internação Ginecobstétrica | H16: Daniella Gomes De Oliveira Costa
A17: 2.1 | B17: Diretoria Técnica | C17: 2.1.35 | D17: Gerência de Cuidados Cirúrgicos | E17: Evila Ellen Sa De Moraes Matias | F17: 2.1.35.2 | G17: CME - Centro de Material e Esterilização | H17: Olivia Alves dos Santos
A18: 2.1 | B18: Diretoria Técnica | C18: 2.1.33 | D18: Gerência de Cuidado Materno/Infantil | E18: Camila Nascimento Santos Santana | F18: 2.1.33.3 | G18: CPN - Centro de Parto Normal | H18: Lorena do Nascimento Barreto
A19: 2.1 | B19: Diretoria Técnica | C19: 2.1.34 | D19: Gerência Ambulatorial e do Apoio Diagnóstico | E19: Camila Amanda Cardoso dos Santos | F19: 2.1.34.2 | G19: CTI - Centro de Terapia Infusional | H19: Camila Amanda Cardoso dos Santos
A20: 2.1 | B20: Diretoria Técnica | C20: 00 | D20: Diretoria | E20: Marcelo Lopes Ribeiro | F20: 2.1.11 | G20: Diretoria Técnica | H20: Marcelo Lopes Ribeiro
A21: 2.1 | B21: Diretoria Técnica | C21: 2.1.37 | D21: Equipe Multiprofissional | E21: Alfredo Gomes Barbosa | F21: 2.1.37.1 | G21: FIS - Fisioterapia | H21: Alfredo Gomes Barbosa
A22: 2.1 | B22: Diretoria Técnica | C22: 2.1.37 | D22: Equipe Multiprofissional | E22: Webete da Silva Costa | F22: 2.1.37.2 | G22: FONO - Fonoaudiologia | H22: Webete da Silva Costa
A23: 2.1 | B23: Diretoria Técnica | C23: 0 | D23: Ligado direto a diretoria | E23: Clariane Acário Martins | F23: 2.1.13 | G23: GA - Gerência Assistencial | H23: Clariane Acário Martins
A24: 2.1 | B24: Diretoria Técnica | C24: 00 | D24: Ligado direto a diretoria | E24: Aliny Lopes Coelho | F24: 2.1.14 | G24: GRSS - Gerenciamento de Resíduos de Serviço de Saúde | H24: Aliny Lopes Coelho
A25: 2.1 | B25: Diretoria Técnica | C25: 2.1.34 | D25: Gerência Ambulatorial e do Apoio Diagnóstico | E25: Camila Amanda Cardoso dos Santos | F25: 2.1.34.4 | G25: LAB - Unidade de Análises Clínicas | H25: Camila Amanda Cardoso dos Santos
A26: 2.1 | B26: Diretoria Técnica | C26: 2.1.8 | D26: Coordenação de Internação | E26: Janaina Bernardes Ayer | F26: 2.1.8.5 | G26: NIR - Núcleo Interno de Regulação | H26: Janaina Bernardes Ayer
A27: 2.1 | B27: Diretoria Técnica | C27: 2.1.37 | D27: Equipe Multiprofissional | E27: Flavia de Souza Moura | F27: 2.1.37.3 | G27: Nutrição Clínica | H27: Flavia de Souza Moura
A28: 2.1 | B28: Diretoria Técnica | C28: 00 | D28: Ligado direto a diretoria | E28: Aliny Lopes Coelho | F28: 2.1.18 | G28: NVEH - Núcleo de Vigilância Epidemiológica Hospitalar | H28: Aliny Lopes Coelho
A29: 2.1 | B29: Diretoria Técnica | C29: 2.1.36 | D29: Gerência de Cuidados Clínicos Intensivos | E29: Mayara Soares Honório | F29: 2.1.36.1 | G29: P.S - Pronto Socorro | H29: Mayara Soares Honório
A30: 2.1 | B30: Diretoria Técnica | C30: 2.1.33 | D30: Gerência de Cuidado Materno/Infantil | E30: Camila Nascimento Santos Santana | F30: 2.1.33.4 | G30: PAM - Pronto Atendimento Materno | H30: Camila Nascimento Santos Santana
A31: 2.1 | B31: Diretoria Técnica | C31: 2.1.33 | D31: Gerência de Cuidado Materno/Infantil | E31: Camila Nascimento Santos Santana | F31: 2.1.33.5 | G31: PED - Unidade de Internação Pediátrica | H31: Larissa Talita da Silva
A32: 2.1 | B32: Diretoria Técnica | C32: 2.1.37 | D32: Equipe Multiprofissional | E32: Mariana Lopes de Almeida | F32: 2.1.37.4 | G32: PSICC- Psicologia Clínica | H32: Mariana Lopes de Almeida
A33: 2.1 | B33: Diretoria Técnica | C33: 2.1.36 | D33: Gerência de Cuidados Clínicos Intensivos | E33: Mayara Soares Honório | F33: 2.1.36.2 | G33: PSICO - Unidade de Atendimento a Saúde Mental | H33: Marisol Luise Vilhene da Silva
A34: 2.1 | B34: Diretoria Técnica | C34: 2.1.8 | D34: Coordenação de Internação | E34: Janaina Bernardes Ayer | F34: 2.1.8.7 | G34: REC - Recepção | H34: Janaina Bernardes Ayer
A35: 2.1 | B35: Diretoria Técnica | C35: 2.1.34 | D35: Gerência Ambulatorial e do Apoio Diagnóstico | E35: Camila Amanda Cardoso dos Santos | F35: 2.1.34.3 | G35: SADT - Unidade de Diagnóstico Por Imagem | H35: Nadja Keilane Dantas Espinola
... A63: 3.1 | B63: Dir. Administrativa/Financeira | C63: 000 | D63: Ligado direto a diretoria | E63: Gleyce Kelly Damaceno Barros Cavalcante | F63: 3.1.8 | G63: OPME - Órtese Prótese e Materiais Especiais | H63: Gleyce Kelly Damaceno Barros Cavalcante

Sheet AÇÕES
A1: Título | B1: Plano de Ação | C1: Tipo | D1: Setor | E1: Responsável | F1: Início Previsto | G1: Início Realizado | H1: Fim Previsto | I1: Fim Realizado | J1: Progresso | K1: Status
A2: Nível 1 - 1.1.17.1 Requisito: Definir diretrizes formais para prevenção, controle de infecção e biossegurança e implementa ações sistemáticas (CORE) | B2: ONA 2026: Grupo 1.1.17 - Prevenção e Controle de Infecção e Biossegurança | C2: ONA | D2: =_xlfn.XLOOKUP(E2,Organograma!H:H,Organograma!G:G,"") -> GRSS - Gerenciamento de Resíduos de Serviço de Saúde | E2: Aliny Lopes Coelho | F2: 46025 | G2: 46331 | H2: 46173 | I2: n/d | J2: 0.5 | K2: Em Andamento
A3: Nível 1 - 1.1.17.2 Requisito: Prover condições para que o Serviço de Prevenção, Controle de Infecção e Biossegurança assessore tecnicamente os processos | B3: ONA 2026: Grupo 1.1.17 - Prevenção e Controle de Infecção e Biossegurança | C3: ONA | D3: =_xlfn.XLOOKUP(E3,Organograma!H:H,Organograma!G:G,"") -> GRSS - Gerenciamento de Resíduos de Serviço de Saúde | E3: Aliny Lopes Coelho | F3: 46025 | G3: 46331 | H3: 46173 | I3: n/d | J3: 0.5 | K3: Em Andamento
A4: Nível 2 - 1.1.17.3 Requisito: Monitorar e gerenciar o Programa de Prevenção, Controle de Infecção e Biossegurança com base em evidências, análises de causa | B4: ONA 2026: Grupo 1.1.17 - Prevenção e Controle de Infecção e Biossegurança | C4: ONA | D4: =_xlfn.XLOOKUP(E4,Organograma!H:H,Organograma!G:G,"") -> GRSS - Gerenciamento de Resíduos de Serviço de Saúde | E4: Aliny Lopes Coelho | F4: 46025 | G4: n/d | H4: 46173 | I4: n/d | J4: 0 | K4: Não Iniciada
A5: Nível 3 - 1.1.17.4 Requisito: Utilizar os resultados do Programa de Prevenção, Controle de Infecção e Biossegurança para promover ciclos de melhoria (CORE) | B5: ONA 2026: Grupo 1.1.17 - Prevenção e Controle de Infecção e Biossegurança | C5: ONA | D5: =_xlfn.XLOOKUP(E5,Organograma!H:H,Organograma!G:G,"") -> GRSS - Gerenciamento de Resíduos de Serviço de Saúde | E5: Aliny Lopes Coelho | F5: 46025 | G5: n/d | H5: 46173 | I5: n/d | J5: 0 | K5: Não Iniciada
A6: Nível 1 - 1.1.18.1 Requisito: Estabelecer canal formal para comunicação de questões relacionadas à integridade, conformidade (compliance), dilemas éticos | B6: ONA 2026: Grupo 1.1.17 - Prevenção e Controle de Infecção e Biossegurança | C6: ONA | D6: =_xlfn.XLOOKUP(E6,Organograma!H:H,Organograma!G:G,"") -> GRSS - Gerenciamento de Resíduos de Serviço de Saúde | E6: Aliny Lopes Coelho | F6: 46025 | G6: n/d | H6: 46173 | I6: n/d | J6: 0 | K6: Não Iniciada
A7: Nível 1 - 1.1.18.2 Requisito: Estabelecer, implementar e manter um plano de comunicação estruturado para interação com os públicos interno e externo. | B7: ONA 2026: Grupo 1.1.17 - Prevenção e Controle de Infecção e Biossegurança | C7: ONA | D7: =_xlfn.XLOOKUP(E7,Organograma!H:H,Organograma!G:G,"") -> GRSS - Gerenciamento de Resíduos de Serviço de Saúde | E7: Aliny Lopes Coelho | F7: 46025 | G7: n/d | H7: 46173 | I7: n/d | J7: 0 | K7: Não Iniciada
A8: Nível 1 - 1.1.18.3 Requisito: Estabelecer, implementar e manter meios e canais acessíveis e eficazes de comunicação com pacientes/clientes (CORE) | B8: ONA 2026: Grupo 1.1.17 - Prevenção e Controle de Infecção e Biossegurança | C8: ONA | D8: =_xlfn.XLOOKUP(E8,Organograma!H:H,Organograma!G:G,"") -> GRSS - Gerenciamento de Resíduos de Serviço de Saúde | E8: Aliny Lopes Coelho | F8: 46025 | G8: n/d | H8: 46173 | I8: n/d | J8: 0 | K8: Não Iniciada
A9: Nível 1 - 1.1.18.4 Requisito: Estabelecer, implementar e manter meios e canais de comunicação eficazes entre os diferentes níveis hierárquicos e perfis | B9: ONA 2026: Grupo 1.1.17 - Prevenção e Controle de Infecção e Biossegurança | C9: ONA | D9: =_xlfn.XLOOKUP(E9,Organograma!H:H,Organograma!G:G,"") -> GRSS - Gerenciamento de Resíduos de Serviço de Saúde | E9: Aliny Lopes Coelho | F9: 46025 | G9: n/d | H9: 46173 | I9: n/d | J9: 0 | K9: Não Iniciada
A10: Nível 2 - .1.18.5 Requisito: Avaliar os canais de comunicação, identificando causas de falhas e promovendo ações de melhoria contínua. | B10: ONA 2026: Grupo 1.1.17 - Prevenção e Controle de Infecção e Biossegurança | C10: ONA | D10: =_xlfn.XLOOKUP(E10,Organograma!H:H,Organograma!G:G,"") -> GRSS - Gerenciamento de Resíduos de Serviço de Saúde | E10: Aliny Lopes Coelho | F10: 46025 | G10: n/d | H10: 46173 | I10: n/d | J10: 0 | K10: Não Iniciada
A11: Nível 3 - 1.1.18.6 Requisito: Utilizar os resultados da comunicação para avaliar a efetividade dos canais e promover ciclos de melhoria. | B11: ONA 2026: Grupo 1.1.17 - Prevenção e Controle de Infecção e Biossegurança | C11: ONA | D11: =_xlfn.XLOOKUP(E11,Organograma!H:H,Organograma!G:G,"") -> GRSS - Gerenciamento de Resíduos de Serviço de Saúde | E11: Aliny Lopes Coelho | F11: 46025 | G11: n/d | H11: 46173 | I11: n/d | J11: 0 | K11: Não Iniciada
A12: Nível 1 - 1.1.19.1 Requisito: Definir, divulgar e assegurar o cumprimento dos direitos e deveres dos pacientes e usuários dos serviços | B12: ONA 2026: Grupo 1.1.17 - Prevenção e Controle de Infecção e Biossegurança | C12: ONA | D12: =_xlfn.XLOOKUP(E12,Organograma!H:H,Organograma!G:G,"") -> GRSS - Gerenciamento de Resíduos de Serviço de Saúde | E12: Aliny Lopes Coelho | F12: 46025 | G12: n/d | H12: 46173 | I12: n/d | J12: 0 | K12: Não Iniciada
A13: Nível 1 - 1.1.19.2 Requisito: Assegurar que todos os profissionais envolvidos na assistência recebam educação e capacitação que promovam o cuidado centrado | B13: ONA 2026: Grupo 1.1.17 - Prevenção e Controle de Infecção e Biossegurança | C13: ONA | D13: =_xlfn.XLOOKUP(E13,Organograma!H:H,Organograma!G:G,"") -> GRSS - Gerenciamento de Resíduos de Serviço de Saúde | E13: Aliny Lopes Coelho | F13: 46025 | G13: n/d | H13: 46173 | I13: n/d | J13: 0 | K13: Não Iniciada
A14: Nível 1 - 1.1.19.3 Requisito: Fornecer aos pacientes e usuários informações claras, acessíveis e compreensíveis sobre suas necessidades de cuidado, alternativas | B14: ONA 2026: Grupo 1.1.17 - Prevenção e Controle de Infecção e Biossegurança | C14: ONA | D14: =_xlfn.XLOOKUP(E14,Organograma!H:H,Organograma!G:G,"") -> GRSS - Gerenciamento de Resíduos de Serviço de Saúde | E14: Aliny Lopes Coelho | F14: 46025 | G14: n/d | H14: 46173 | I14: n/d | J14: 0 | K14: Não Iniciada
A15: Nível 1 - 1.1.19.4 Requisito: Assegurar a participação ativa do paciente e/ou de seus representantes nas decisões relacionadas ao seu cuidado e tratamento | B15: ONA 2026: Grupo 1.1.17 - Prevenção e Controle de Infecção e Biossegurança | C15: ONA | D15: =_xlfn.XLOOKUP(E15,Organograma!H:H,Organograma!G:G,"") -> GRSS - Gerenciamento de Resíduos de Serviço de Saúde | E15: Aliny Lopes Coelho | F15: 46025 | G15: n/d | H15: 46173 | I15: n/d | J15: 0 | K15: Não Iniciada
... A22: Nível 3 - 1.1.19.11 Requisito: Possuir processos sistemáticos para consultar e envolver pacientes, familiares e a comunidade na avaliação e melhoria contínua | B22: ONA 2026: Grupo 1.1.17 - Prevenção e Controle de Infecção e Biossegurança | C22: ONA | D22: =_xlfn.XLOOKUP(E22,Organograma!H:H,Organograma!G:G,"") -> GRSS - Gerenciamento de Resíduos de Serviço de Saúde | E22: Aliny Lopes Coelho | F22: 46025 | G22: n/d | H22: 46173 | I22: n/d | J22: 0 | K22: Não Iniciada
A23: 4.8.1 Requisito: Monitorar a qualidade da água em todas as etapas relacionadas à assistência nutricional (CORE) | B23: ONA 2026: Subseção 4.8 Nutrição | C23: ONA | D23: =_xlfn.XLOOKUP(E23,Organograma!H:H,Organograma!G:G,"") -> SND - Serviço de Nutrição e Dietética | E23: Ana Luiza Timoteo Costa | F23: 46025 | G23: 46147 | H23: 46173 | I23: n/d | J23: 0.5 | K23: Em Andamento
A24: 4.8.2 Requisito: Planejar e monitorar a demanda de dietas | B24: ONA 2026: Subseção 4.8 Nutrição | C24: ONA | D24: =_xlfn.XLOOKUP(E24,Organograma!H:H,Organograma!G:G,"") -> SND - Serviço de Nutrição e Dietética | E24: Ana Luiza Timoteo Costa | F24: 46025 | G24: 46105 | H24: 46173 | I24: n/d | J24: 0.5 | K24: Em Andamento
A25: 4.8.3 Requisito: Dispor de mecanismos e procedimentos para a identificação e rastreabilidade de alimentos e refeições | B25: ONA 2026: Subseção 4.8 Nutrição | C25: ONA | D25: =_xlfn.XLOOKUP(E25,Organograma!H:H,Organograma!G:G,"") -> SND - Serviço de Nutrição e Dietética | E25: Ana Luiza Timoteo Costa | F25: 46025 | G25: 46104 | H25: 46173 | I25: n/d | J25: 0.75 | K25: Em Andamento
A26: 4.8.4 Requisito: Dispor de mecanismos e procedimentos para o monitoramento e conservação de alimentos e refeições (CORE) | B26: ONA 2026: Subseção 4.8 Nutrição | C26: ONA | D26: =_xlfn.XLOOKUP(E26,Organograma!H:H,Organograma!G:G,"") -> SND - Serviço de Nutrição e Dietética | E26: Ana Luiza Timoteo Costa | F26: 46025 | G26: 46104 | H26: 46173 | I26: n/d | J26: 0.75 | K26: Em Andamento
A27: 4.8.5 Requisito: Dispor de mecanismos e procedimentos para o porcionamento, transporte, distribuição e amostragem de alimentos e refeições (CORE) | B27: ONA 2026: Subseção 4.8 Nutrição | C27: ONA | D27: =_xlfn.XLOOKUP(E27,Organograma!H:H,Organograma!G:G,"") -> SND - Serviço de Nutrição e Dietética | E27: Ana Luiza Timoteo Costa | F27: 46025 | G27: 46145 | H27: 46173 | I27: n/d | J27: 0.5 | K27: Em Andamento
A28: 4.8.7 Requisito: Planejar e monitorar a demanda de terapia nutricional parenteral. | B28: ONA 2026: Subseção 4.8 Nutrição | C28: ONA | D28: =_xlfn.XLOOKUP(E28,Organograma!H:H,Organograma!G:G,"") -> SND - Serviço de Nutrição e Dietética | E28: Ana Luiza Timoteo Costa | F28: 46025 | G28: 46106 | H28: 46173 | I28: n/d | J28: 0.75 | K28: Em Andamento
A29: 4.8.8 Requisito: Dispor de mecanismos e procedimentos para a identificação e rastreabilidade de dietas enterais, módulos e suplementos/complementos nutricionais | B29: ONA 2026: Subseção 4.8 Nutrição | C29: ONA | D29: =_xlfn.XLOOKUP(E29,Organograma!H:H,Organograma!G:G,"") -> SND - Serviço de Nutrição e Dietética | E29: Ana Luiza Timoteo Costa | F29: 46025 | G29: 46267 | H29: 46173 | I29: n/d | J29: 0.5 | K29: Em Andamento
A30: 4.8.9 Requisito: Dispor de mecanismos e procedimentos para o monitoramento e a conservação de dietas enterais, módulos e suplementos/complementos nutricionais | B30: ONA 2026: Subseção 4.8 Nutrição | C30: ONA | D30: =_xlfn.XLOOKUP(E30,Organograma!H:H,Organograma!G:G,"") -> SND - Serviço de Nutrição e Dietética | E30: Ana Luiza Timoteo Costa | F30: 46025 | G30: 46108 | H30: 46173 | I30: n/d | J30: 0.75 | K30: Em Andamento
A31: 4.8.10 Requisito: Dispor de mecanismos e procedimentos para o encaminhamento, distribuição e amostragem de dietas enterais, módulos e suplementos/complementos | B31: ONA 2026: Subseção 4.8 Nutrição | C31: ONA | D31: =_xlfn.XLOOKUP(E31,Organograma!H:H,Organograma!G:G,"") -> SND - Serviço de Nutrição e Dietética | E31: Ana Luiza Timoteo Costa | F31: 46025 | G31: 46099 | H31: 46173 | I31: n/d | J31: 0.75 | K31: Em Andamento
A32: 4.8.11 Requisito: Estabelecer e implementar critérios e procedimentos para a análise técnica das prescrições dietéticas e nutricionais, assegurando a adequação | B32: ONA 2026: Subseção 4.8 Nutrição | C32: ONA | D32: =_xlfn.XLOOKUP(E32,Organograma!H:H,Organograma!G:G,"") -> SND - Serviço de Nutrição e Dietética | E32: Ana Luiza Timoteo Costa | F32: 46025 | G32: 46097 | H32: 46173 | I32: n/d | J32: 0.75 | K32: Em Andamento
A33: 4.8.12 Requisito: Planejar e acompanhar a demanda de leite humano e fórmulas infantis, conforme perfil de pacientes | B33: ONA 2026: Subseção 4.8 Nutrição | C33: ONA | D33: =_xlfn.XLOOKUP(E33,Organograma!H:H,Organograma!G:G,"") -> SND - Serviço de Nutrição e Dietética | E33: Ana Luiza Timoteo Costa | F33: 46142 | G33: 46105 | H33: 46173 | I33: n/d | J33: 0.5 | K33: Em Andamento
A34: 4.8.13 Requisito: Dispor de uma sistemática para mobilização de doadoras de leite humano | B34: ONA 2026: Subseção 4.8 Nutrição | C34: ONA | D34: =_xlfn.XLOOKUP(E34,Organograma!H:H,Organograma!G:G,"") -> SND - Serviço de Nutrição e Dietética | E34: Ana Luiza Timoteo Costa | F34: 46025 | G34: 46106 | H34: 46173 | I34: n/d | J34: 0.5 | K34: Em Andamento
... A41: 4.8.20 Requisito: Dispor de mecanismos e procedimentos para o encaminhamento, distribuição e amostragem do leite humano | B41: ONA 2026: Subseção 4.8 Nutrição | C41: ONA | D41: =_xlfn.XLOOKUP(E41,Organograma!H:H,Organograma!G:G,"") -> SND - Serviço de Nutrição e Dietética | E41: Ana Luiza Timoteo Costa | F41: 46025 | G41: 46111 | H41: 46173 | I41: n/d | J41: 0.5 | K41: Em Andamento
A42: 4.10.1 Requisito: Estabelecer, implementar e manter um plano de contingência para situações de descontinuidade no acesso a dados e informações (CORE) | B42: ONA 2026: Subseção 4.10 Gestão da Tecnologia e Segurança da Informação | C42: ONA | D42: =_xlfn.XLOOKUP(E42,Organograma!H:H,Organograma!G:G,"") -> TI - Serviço de Tecnologia de Informação | E42: Andrew Silva de Lima | F42: 46025 | G42: n/d | H42: 46173 | I42: n/d | J42: 0 | K42: Não Iniciada
A43: 4.10.2 Requisito: Dispor de informações integradas do paciente/cliente, permitindo acesso ao histórico dos atendimentos realizados pela equipe multidisciplinar | B43: ONA 2026: Subseção 4.10 Gestão da Tecnologia e Segurança da Informação | C43: ONA | D43: =_xlfn.XLOOKUP(E43,Organograma!H:H,Organograma!G:G,"") -> TI - Serviço de Tecnologia de Informação | E43: Andrew Silva de Lima | F43: 46025 | G43: n/d | H43: 46173 | I43: n/d | J43: 0 | K43: Não Iniciada
A44: 4.10.3 Requisito: Estabelecer, implementar e manter sistemática p/ registros e evoluções da equipe multidisciplinar, permitindo a continuidade do cuidado (CORE) | B44: ONA 2026: Subseção 4.10 Gestão da Tecnologia e Segurança da Informação | C44: ONA | D44: =_xlfn.XLOOKUP(E44,Organograma!H:H,Organograma!G:G,"") -> TI - Serviço de Tecnologia de Informação | E44: Andrew Silva de Lima | F44: 46025 | G44: n/d | H44: 46173 | I44: n/d | J44: 0 | K44: Não Iniciada
A45: 4.10.4 Requisito: Estabelecer, implementar e manter procedimento para avaliação sistemática da qualidade das evoluções, registros e informações (CORE) | B45: ONA 2026: Subseção 4.10 Gestão da Tecnologia e Segurança da Informação | C45: ONA | D45: =_xlfn.XLOOKUP(E45,Organograma!H:H,Organograma!G:G,"") -> TI - Serviço de Tecnologia de Informação | E45: Andrew Silva de Lima | F45: 46025 | G45: n/d | H45: 46173 | I45: n/d | J45: 0 | K45: Não Iniciada
A46: 4.10.5 Requisito: Estabelecer, implementar e manter um método de coleta, análise e disponibilização de dados para apoiar a tomada de decisão em todas as áreas | B46: ONA 2026: Subseção 4.10 Gestão da Tecnologia e Segurança da Informação | C46: ONA | D46: =_xlfn.XLOOKUP(E46,Organograma!H:H,Organograma!G:G,"") -> TI - Serviço de Tecnologia de Informação | E46: Andrew Silva de Lima | F46: 46025 | G46: n/d | H46: 46173 | I46: n/d | J46: 0 | K46: Não Iniciada
A47: 4.10.6 Requisito: Estabelecer e manter orientações claras aos usuários quanto às regras de segurança da informação (CORE) | B47: ONA 2026: Subseção 4.10 Gestão da Tecnologia e Segurança da Informação | C47: ONA | D47: =_xlfn.XLOOKUP(E47,Organograma!H:H,Organograma!G:G,"") -> TI - Serviço de Tecnologia de Informação | E47: Andrew Silva de Lima | F47: 46025 | G47: n/d | H47: 46173 | I47: n/d | J47: 0 | K47: Não Iniciada
A48: 4.10.7 Requisito: Estabelecer e implementar diretrizes claras para as permissões de acesso ao prontuário, assegurando a privacidade e a confidencialidade | B48: ONA 2026: Subseção 4.10 Gestão da Tecnologia e Segurança da Informação | C48: ONA | D48: =_xlfn.XLOOKUP(E48,Organograma!H:H,Organograma!G:G,"") -> TI - Serviço de Tecnologia de Informação | E48: Andrew Silva de Lima | F48: 46025 | G48: n/d | H48: 46173 | I48: n/d | J48: 0 | K48: Não Iniciada
A49: 4.10.8 Requisito: Estabelecer, implementar e manter uma sistemática para a organização e padronização da estrutura e do conteúdo do prontuário/dados do paciente | B49: ONA 2026: Subseção 4.10 Gestão da Tecnologia e Segurança da Informação | C49: ONA | D49: =_xlfn.XLOOKUP(E49,Organograma!H:H,Organograma!G:G,"") -> TI - Serviço de Tecnologia de Informação | E49: Andrew Silva de Lima | F49: 46025 | G49: n/d | H49: 46173 | I49: n/d | J49: 0 | K49: Não Iniciada
A50: 4.10.9 Requisito: Estabelecer programa de privacidade de dados, especificando o fluxo de acesso e a tratativa das informações. | B50: ONA 2026: Subseção 4.10 Gestão da Tecnologia e Segurança da Informação | C50: ONA | D50: =_xlfn.XLOOKUP(E50,Organograma!H:H,Organograma!G:G,"") -> TI - Serviço de Tecnologia de Informação | E50: Andrew Silva de Lima | F50: 46025 | G50: n/d | H50: 46173 | I50: n/d | J50: 0 | K50: Não Iniciada
A51: 4.10.10 Requisito: Estabelecer mecanismos de segurança para garantir a proteção, confidencialidade e integridade nas comunicações virtuais com pacientes/usuário | B51: ONA 2026: Subseção 4.10 Gestão da Tecnologia e Segurança da Informação | C51: ONA | D51: =_xlfn.XLOOKUP(E51,Organograma!H:H,Organograma!G:G,"") -> TI - Serviço de Tecnologia de Informação | E51: Andrew Silva de Lima | F51: 46025 | G51: n/d | H51: 46173 | I51: n/d | J51: 0 | K51: Não Iniciada
A52: 4.10.11 Requisito: Estabelecer, implementar e manter uma sistemática para qualificar e testar os sistemas de informática e softwares antes da entrada em uso | B52: ONA 2026: Subseção 4.10 Gestão da Tecnologia e Segurança da Informação | C52: ONA | D52: =_xlfn.XLOOKUP(E52,Organograma!H:H,Organograma!G:G,"") -> TI - Serviço de Tecnologia de Informação | E52: Andrew Silva de Lima | F52: 46025 | G52: n/d | H52: 46173 | I52: n/d | J52: 0 | K52: Não Iniciada
...

Sheet INDICADORES
A1: TiPO | B1: Indicadores | C1: Status | D1: Responsavel | E1: Setor | F1: Data da Verificação | G1: Serial
A2: Atraso na Alimentação | B2: Percentual de Acurácia de Alto Custo - Almoxarifado (Resultado) | C2: Fora do Prazo | D2: =_xlfn.XLOOKUP(E2,Organograma!G:G,Organograma!H:H,"") -> Madson de Souza Santos | E2: ALM - Almoxarifado | F2: 08/05/2026 | G2: NC 3318 / 2026
A3: Atraso na Análise | B3: Percentual de Acurácia de Alto Custo - Almoxarifado (Resultado) | C3: Fora do Prazo | D3: =_xlfn.XLOOKUP(E3,Organograma!G:G,Organograma!H:H,"") -> Madson de Souza Santos | E3: ALM - Almoxarifado | F3: 11/05/2026 | G3: NC 3441 / 2026
A4: Atraso na Alimentação | B4: Percentual de Atendimento (Processo) | C4: Fora do Prazo | D4: =_xlfn.XLOOKUP(E4,Organograma!G:G,Organograma!H:H,"") -> Madson de Souza Santos | E4: ALM - Almoxarifado | F4: 08/05/2026 | G4: NC 3316 / 2026
A5: Atraso na Análise | B5: Percentual de Atendimento (Processo) | C5: Fora do Prazo | D5: =_xlfn.XLOOKUP(E5,Organograma!G:G,Organograma!H:H,"") -> Madson de Souza Santos | E5: ALM - Almoxarifado | F5: 11/05/2026 | G5: NC 3439 / 2026
A6: Atraso na Alimentação | B6: Perda Por Validade E Avarias (Resultado) | C6: Fora do Prazo | D6: =_xlfn.XLOOKUP(E6,Organograma!G:G,Organograma!H:H,"") -> Madson de Souza Santos | E6: ALM - Almoxarifado | F6: 08/05/2026 | G6: NC 3317 / 2026
A7: Atraso na Análise | B7: Perda Por Validade E Avarias (Resultado) | C7: Fora do Prazo | D7: =_xlfn.XLOOKUP(E7,Organograma!G:G,Organograma!H:H,"") -> Madson de Souza Santos | E7: ALM - Almoxarifado | F7: 11/05/2026 | G7: NC 3440 / 2026
A8: Atraso na Análise | B8: Quantidade de Itens Solicitados (Estrutura) | C8: Fora do Prazo | D8: =_xlfn.XLOOKUP(E8,Organograma!G:G,Organograma!H:H,"") -> Madson de Souza Santos | E8: ALM - Almoxarifado | F8: 11/05/2026 | G8: NC 3438 / 2026
A9: Atraso na Análise | B9: Percentual de Pacientes com Tempo de Espera Superior a 30 Minutos no Ambulatório (Processo) | C9: Fora do Prazo | D9: =_xlfn.XLOOKUP(E9,Organograma!G:G,Organograma!H:H,"") -> Camila Amanda Cardoso dos Santos | E9: AMB - Unidade Ambulatorial | F9: 12/05/2026 | G9: NC 3574 / 2026
A10: Atraso na Análise | B10: Taxa de Absenteismo em Consultas Ambulatoriais (Resultado) | C10: Fora do Prazo | D10: =_xlfn.XLOOKUP(E10,Organograma!G:G,Organograma!H:H,"") -> Camila Amanda Cardoso dos Santos | E10: AMB - Unidade Ambulatorial | F10: 12/05/2026 | G10: NC 3573 / 2026
A11: Atraso na Análise | B11: Acompanhamento Transfusional (Processo) | C11: Fora do Prazo | D11: =_xlfn.XLOOKUP(E11,Organograma!G:G,Organograma!H:H,"") -> Camila Amanda Cardoso dos Santos | E11: AT - Agência Transfusional | F11: 12/05/2026 | G11: NC 3588 / 2026
A12: Atraso na Alimentação | B12: Auditoria Não Conformidade Transfusional (Processo) | C12: Fora do Prazo | D12: =_xlfn.XLOOKUP(E12,Organograma!G:G,Organograma!H:H,"") -> Camila Amanda Cardoso dos Santos | E12: AT - Agência Transfusional | F12: 08/05/2026 | G12: NC 3413 / 2026
A13: Atraso na Alimentação | B13: Cobertura de Postos de Acesso (Estrutura) | C13: Fora do Prazo | D13: =_xlfn.XLOOKUP(E13,Organograma!G:G,Organograma!H:H,"") -> Janaina Bernardes Ayer | E13: CA - Controle de Acesso | F13: 08/05/2026 | G13: NC 3360 / 2026
... A286: Atraso na Análise | B286: Diárias de Pacientes na Unidade de Internação Ortopédica (Estrutura) | C286: Fora do Prazo | D286: =_xlfn.XLOOKUP(E286,Organograma!G:G,Organograma!H:H,"") -> Debora De Oliveira Alvarenga | E286: UIO - Unidade de Internação Ortopédica | F286: 13/05/2026 | G286: NC 3606 / 2026
A287: Alimentação em dia | B287: Absenteísmo (Resultado) | C287: Dentro do Prazo | D287: =_xlfn.XLOOKUP(E287,Organograma!G:G,Organograma!H:H,"") -> Mylena Justino da Silva Brito | E287: APGQ - Assessoria de Planejamento e Gestão da Qualidade | F287: 46155 | G287: n/a
A288: Alimentação em dia | B288: Auditorias dos Processos Laboratoriais (Processo) | C288: Dentro do Prazo | D288: =_xlfn.XLOOKUP(E288,Organograma!G:G,Organograma!H:H,"") -> Camila Amanda Cardoso dos Santos | E288: LAB - Unidade de Análises Clínicas | F288: 46155 | G288: n/a
A289: Alimentação em dia | B289: Acompanhamento Transfusional (Processo) | C289: Dentro do Prazo | D289: =_xlfn.XLOOKUP(E289,Organograma!G:G,Organograma!H:H,"") -> Camila Amanda Cardoso dos Santos | E289: AT - Agência Transfusional | F289: 46155 | G289: n/a
A290: Alimentação em dia | B290: Assertividade da Alta Hospitalar conforme Previsão Médica - Clínica Cirúrgica (Resultado) | C290: Dentro do Prazo | D290: =_xlfn.XLOOKUP(E290,Organograma!G:G,Organograma!H:H,"") -> Debora De Oliveira Alvarenga | E290: UICC - Unidade de Internação Cirúrgica | F290: 46155 | G290: n/a
A291: Alimentação em dia | B291: Assertividade da Alta Hospitalar conforme Previsão Médica (Clínica Ortopédica) (Resultado) | C291: Dentro do Prazo | D291: =_xlfn.XLOOKUP(E291,Organograma!G:G,Organograma!H:H,"") -> Debora De Oliveira Alvarenga | E291: UIO - Unidade de Internação Ortopédica | F291: 46155 | G291: n/a
A292: Alimentação em dia | B292: Assuntos Diversos | C292: Dentro do Prazo | D292: =_xlfn.XLOOKUP(E292,Organograma!G:G,Organograma!H:H,"") -> Mylena Justino da Silva Brito | E292: APGQ - Assessoria de Planejamento e Gestão da Qualidade | F292: 46155 | G292: n/a
A293: Alimentação em dia | B293: Atendimentos Ambulatórios Não Médicos | C293: Dentro do Prazo | D293: =_xlfn.XLOOKUP(E293,Organograma!G:G,Organograma!H:H,"") -> Mylena Justino da Silva Brito | E293: APGQ - Assessoria de Planejamento e Gestão da Qualidade | F293: 46155 | G293: n/a
A294: Alimentação em dia | B294: Atendimentos no Pronto Socorro (Estrutura) | C294: Dentro do Prazo | D294: =_xlfn.XLOOKUP(E294,Organograma!G:G,Organograma!H:H,"") -> Mylena Justino da Silva Brito | E294: APGQ - Assessoria de Planejamento e Gestão da Qualidade | F294: 46155 | G294: n/a
A295: Alimentação em dia | B295: Auditoria Não Conformidade Transfusional (Processo) | C295: Dentro do Prazo | D295: =_xlfn.XLOOKUP(E295,Organograma!G:G,Organograma!H:H,"") -> Camila Amanda Cardoso dos Santos | E295: AT - Agência Transfusional | F295: 46155 | G295: n/a
A296: Alimentação em dia | B296: Índice de Hora de Treinamento por Colaborador (Resultado) | C296: Dentro do Prazo | D296: =_xlfn.XLOOKUP(E296,Organograma!G:G,Organograma!H:H,"") -> Cleudimara Pereira Maciel Souza | E296: NEP - Núcleo de Educação Permanente | F296: 46155 | G296: n/a
A297: Alimentação em dia | B297: Avaliação de Desempenho dos Internos/residentes (Resultado) | C297: Dentro do Prazo | D297: =_xlfn.XLOOKUP(E297,Organograma!G:G,Organograma!H:H,"") -> Cintia Kelciane Gomes de Oliveira | E297: CEP - Centro de Ensino e Pesquisa | F297: 46155 | G297: n/a
A298: Alimentação em dia | B298: Cobertura De Estoque De Itens Críticos (Processo) | C298: Dentro do Prazo | D298: =_xlfn.XLOOKUP(E298,Organograma!G:G,Organograma!H:H,"") -> Gleyce Kelly Damaceno Barros Cavalcante | E298: SUP - Suprimentos | F298: 46155 | G298: n/a
... A611: Atraso na Alimentação | B611: Total de Acesso de Pacientes (Processo) | C611: Fora do Prazo | D611: =_xlfn.XLOOKUP(E611,Organograma!G:G,Organograma!H:H,"") -> Janaina Bernardes Ayer | E611: REC - Recepção | F611: 46155 | G611: n/a
A612: Análise em dia | B612: Absenteísmo (Resultado) | C612: Dentro do Prazo | D612: Mylena Justino da Silva Brito | E612: APGQ - Assessoria de Planejamento e Gestão da Qualidade | F612: 46155 | G612: n/a
A613: Análise em dia | B613: Auditorias dos Processos Laboratoriais (Processo) | C613: Dentro do Prazo | D613: Camila Amanda Cardoso dos Santos | E613: LAB - Unidade de Análises Clínicas | F613: 46155 | G613: n/a
A614: Análise em dia | B614: Acompanhamento Transfusional (Processo) | C614: Dentro do Prazo | D614: Camila Amanda Cardoso dos Santos | E614: AT - Agência Transfusional | F614: 46155 | G614: n/a
A615: Análise em dia | B615: Assertividade da Alta Hospitalar conforme Previsão Médica - Clínica Cirúrgica (Resultado) | C615: Dentro do Prazo | D615: Debora De Oliveira Alvarenga | E615: UICC - Unidade de Internação Cirúrgica | F615: 46155 | G615: n/a
A616: Análise em dia | B616: Assertividade da Alta Hospitalar conforme Previsão Médica (Clínica Ortopédica) (Resultado) | C616: Dentro do Prazo | D616: Debora De Oliveira Alvarenga | E616: UIO - Unidade de Internação Ortopédica | F616: 46155 | G616: n/a
A617: Análise em dia | B617: Assuntos Diversos | C617: Dentro do Prazo | D617: Mylena Justino da Silva Brito | E617: APGQ - Assessoria de Planejamento e Gestão da Qualidade | F617: 46155 | G617: n/a
A618: Análise em dia | B618: Atendimentos Ambulatórios Não Médicos | C618: Dentro do Prazo | D618: Mylena Justino da Silva Brito | E618: APGQ - Assessoria de Planejamento e Gestão da Qualidade | F618: 46155 | G618: n/a
A619: Análise em dia | B619: Atendimentos no Pronto Socorro (Estrutura) | C619: Dentro do Prazo | D619: Mylena Justino da Silva Brito | E619: APGQ - Assessoria de Planejamento e Gestão da Qualidade | F619: 46155 | G619: n/a
A620: Análise em dia | B620: Auditoria Não Conformidade Transfusional (Processo) | C620: Dentro do Prazo | D620: Camila Amanda Cardoso dos Santos | E620: AT - Agência Transfusional | F620: 46155 | G620: n/a
A621: Análise em dia | B621: Índice de Hora de Treinamento por Colaborador (Resultado) | C621: Dentro do Prazo | D621: Cleudimara Pereira Maciel Souza | E621: NEP - Núcleo de Educação Permanente | F621: 46155 | G621: n/a
A622: Análise em dia | B622: Avaliação de Desempenho dos Internos/residentes (Resultado) | C622: Dentro do Prazo | D622: Cintia Kelciane Gomes de Oliveira | E622: CEP - Centro de Ensino e Pesquisa | F622: 46155 | G622: n/a
A623: Análise em dia | B623: Cobertura De Estoque De Itens Críticos (Processo) | C623: Dentro do Prazo | D623: Gleyce Kelly Damaceno Barros Cavalcante | E623: SUP - Suprimentos | F623: 46155 | G623: n/a
... A898: Análise em dia | B898: Volume de Leite Humano Aproveitado (Resultado) | C898: Dentro do Prazo | D898: Flavia de Souza Moura | E898: BLH - Banco de Leite Humano | F898: 46155 | G898: n/a

Sheet NOTIFICAÇÕES
A1: Titulo | B1: Serial | C1: Departamento/Setor | D1: Responsável | E1: Situação | F1: Anexos | G1: Autor | H1: Criado em | I1: Data da ocorrência | J1: Descrição | K1: Status | L1: Última verificação | M1: Processo Notificado | N1: Processo Notificador | O1: Local onde ocorreu o incidente (Nºleito | P1: Classificação Incidente | Q1: Tipo
A2: RN sem alimentação | B2: INC 1511 / 2026 | C2: Gerência de Cuidados Materno/Infantil / Unidade de Internação Ginecobstétrica - ALCOM | D2: Mylena Justino da Silva Brito | E2: Finalizada | F2: 0 | G2: Ana Carolina da Costa Frazao Cerqueira | H2: 01/01/2026 | I2: 01/01/2026 | J2: por volta das 16h recebo RN D.X.R juntamente com su avó, pois a genitora estava para laqueadura desde as 11h, segundo relato da acompanhante (bem chateada porque o PAM não ofertou leite) RN estava desde as 11h sem se alimentar, segundo acompanhante que chamou a enfermeira 2x e não teve resposta rn apresentando irritabilidade verificamos dx 45mg/dl ofertamos fórmula , aceitou 20ml de 11 até 16h rn não se alimentou | K2: Arquivo | L2: 08/01/2026 | M2: PAM - Pronto Atendimento Materno | N2: Unidade de Internação Gineco Obstétrica | O2: 15 cgo2 | P2: Circunstância de Risco | Q2: Incidente
A3: HPP | B3: INC 1512 / 2026 | C3: Gerência de Cuidados Materno/Infantil / Unidade de Internação Ginecobstétrica - ALCOM | D3: Mylena Justino da Silva Brito | E3: Finalizada | F3: 0 | G3: Vitoria da Silva Couto | H3: 03/01/2026 | I3: 03/01/2026 | J3: Recebo paciente provinda de CC as 16:30 avalio paciente, não foi trocada antes de vir, fralda encharcada com sangramento ativo. 16:35 RECEBO PACIENTE EM LEITO, AVALIO PACIENTE, UTERO ACIMA DA CICATRIZ UMBILICAL COM SANGRAMENTO ATIVO FRALDA CHEIA DE SANGUE, FAÇO MASSAGEM FUNDO DO UTERO COM SAIDA DA DE COAGULOS EM GRANDE QUANTIDADE, ACIONO MEDICO DOUGLAS QUE VEM DE IMEDIATO REALIZA MASSAGEM BIMANUAL CURAGEM COM SAIDA DE GRANDE QUANTIDADE DE COAGULOS E SANGRAMENTO. UTERO CONTRAIDO ABAIXO DA CICATRIZ UMBILICAL, LOQUIOS FISIOLOGICOS, REALIZO TROCA DA FRALDA E PERMANEÇO AVALIANDO SANGRAMENTO. 17:35 ACOMPANHANTE ACIONA EQUIPE INFORMANDO QUE O SANGRAMENTO AUMENTOU, AVALIO PACIENTE FRALDA ENCHARCADA, UTERO CONTRAIDO NA CICATRIZ UMBILICAL. SANGRAMENTO AINDA ATIVO INFORMO MEDICO QUE SOLICITA HEMOGRAMA E PRESCREVE PROTOCOLO DE HPP. REALIZO A TROCA DA FRALDA 17:58 ABERTO PROTOCOLO DE HPP, ACIONO MEDICO DOUGLAS QUE VEM DE IMEDIATO, REALIZADO NOVA CURAGEM MASSAGEM BIMANUAL SAIDA DE COAGULOS EM GRANDE QUANTIDADE REALIZADO S.F 0,9% 500ML COM 4 AMPOLAS DE OXITOSINA + 1 ERGOTRAT PA 8X6 REALIZADO SORO RINGER LACTATO 18:10 REALIZADO 4 AMPOLAS DE TRANSAMIN NO S.F GLICOSADO. 18:25 REALIZADO NOVO ERGOTRAT 18:40 REALIZADO 4 COMP. DE MISO VIA RETAL. 19:00 LOQUIOS FISIOLOGICO | K3: Arquivo | L3: 07/01/2026 | M3: Unidade de Internação Gineco Obstétrica | N3: Unidade de Internação Gineco Obstétrica | O3: CGO2 LT 17 | P3: Evento Adverso Moderado | Q3: Incidente
A4: Encaminhamento de paciente ao setor de Radiologia sem comunicação prévia | B4: INC 1513 / 2026 | C4: Gerência Ambulatorial e de Apoio Diagnóstico / Gerência Ambulatorial e de Apoio Diagnóstico | D4: Mylena Justino da Silva Brito | E4: Convertida | F4: 0 | G4: Nadja Keilane Dantas Espinola | H4: 05/01/2026 | I4: 05/01/2026 | J4: Encaminhamento de um paciente ao setor de Radiologia sem a devida comunicação prévia à equipe assistencial e sem registro formal no fluxo institucional. Tal ocorrência caracteriza falha de processo e quebra de comunicação, configurando risco direto à Segurança do Paciente, conforme previsto: Portaria MS nº 529/2013 - Programa Nacional de Segurança do Paciente (PNSP), que estabelece a comunicação efetiva como uma prática obrigatória para prevenção de incidentes. RDC nº 36/2013 - ANVISA, que institui ações para segurança do paciente e determina que todos os serviços de saúde devem implementar processos padronizados, incluindo a comunicação clara e tempestiva entre setores. Protocolo Nacional de Comunicação Efetiva, que reforça a necessidade de aviso prévio, confirmação de entendimento e continuidade segura do cuidado. Normativas específicas da Radiologia, que exigem avaliação prévia do paciente, revisão de indicações, preparo adequado e garantia de condições técnicas para realização segura do exame. A ausência de comunicação prévia impede que a equipe de Radiologia verifique elementos críticos como: condição clínica e estabilidade do paciente; necessidade de monitoramento; contraindicações específicas (ex.: risco de queda, precauções, alergias, dispositivos implantáveis); preparo adequado para o exame; disponibilidade da sala e da equipe. | K4: Arquivo | L4: 05/01/2026 | M4: PS - Pronto Atendimento Adulto | N4: SADT - Unidade de Diagnóstico Por Imagem | O4: TOMOGRAFIA | Q4: Incidente
A5: Encaminhamento de paciente com tuberculose positiva ao setor de Radiologia sem comunicação prévia | B5: INC 1514 / 2026 | C5: Gerência Ambulatorial e de Apoio Diagnóstico / Gerência Ambulatorial e de Apoio Diagnóstico | D5: Mylena Justino da Silva Brito | E5: Finalizada | F5: 1 | G5: Nadja Keilane Dantas Espinola | H5: 05/01/2026 | I5: 05/01/2026 | J5: Foi encaminhado ao setor de Radiologia um paciente com diagnóstico confirmado de Tuberculose (TB positiva) sem comunicação prévia à equipe do setor, em desacordo com os fluxos assistenciais e protocolos institucionais de segurança. Tal ocorrência configura falha grave de comunicação e de processo assistencial, gerando risco à Segurança do Paciente, exposição ocupacional da equipe e potencial risco sanitário a outros pacientes, especialmente em ambientes compartilhados. A ausência de comunicação prévia impossibilitou a adoção imediata de medidas obrigatórias de precaução, tais como: implementação de precaução por aerossóis; uso adequado de Equipamentos de Proteção Individual (EPI); organização do fluxo seguro do paciente; preparo da sala e redução do risco de transmissão cruzada. Fundamentação legal e normativa A situação contraria dispositivos legais e normativos, entre eles: Portaria MS nº 529/2013 - Programa Nacional de Segurança do Paciente (PNSP); RDC nº 36/2013 - ANVISA, que estabelece ações para prevenção de incidentes e eventos adversos; RDC nº 222/2018 - ANVISA (biossegurança e riscos biológicos); RDC nº 330/2019 - ANVISA, que dispõe sobre Radioproteção e segurança em serviços de diagnóstico por imagem; Normas de Controle de Infecção Relacionada à Assistência à Saúde (IRAS); Protocolos assistenciais para manejo de pacientes com tuberculose, que exigem comunicação prévia e medidas de isolamento. Riscos identificados Exposição ocupacional da equipe de Radiologia; Risco de transmissão da tuberculose a outros pacientes e profissionais; Comprometimento das medidas de biossegurança; Não conformidade sanitária passível de notificação à Vigilância Sanitária. | K5: Arquivo | L5: 08/01/2026 | M5: PS - Pronto Atendimento Adulto | N5: SADT - Unidade de Diagnóstico Por Imagem | O5: TOMOGRAFIA | P5: Circunstância de Risco | Q5: Incidente
A6: APARENTE NÃO HOUVE COLETA DE EXAMES LABORATORIAIS SOLICITADOS | B6: INC 1515 / 2026 | C6: Diretoria Técnica / SCIH - Serviço de Controle de Infecção Hospitalar | D6: Mylena Justino da Silva Brito | E6: Finalizada | F6: 0 | G6: Tiago Soares Fonseca | H6: 05/01/2026 | I6: 05/01/2026 | J6: EM 03/01/26 SOLICITADOS OS EXAMES CULTURA DE FUNGO (SANGUE), SOROLOLGIA ANTI-HAV IGG E IGM, SOROLOGIA T CRUZI, SOROLOGIA HTLV, ANTI-HBC IGG PARA A PACIENTE C.M.S. ATÉ AS 09:06H DA PRESENTE DATA SEM REGISTRO NA PLATAFORMA LIS WEB SE A COLETA FOI OU NÃO REALIZADA. OUTROS EXAMES SOLICITADOS NA MESMA DATA JÁ COM CONFIRMAÇÃO DE COLETA REGISTRADA NA PLATAFORMA. ALÉM DISSO, FOI SOLICITADO O EXAME PROTEINAS TOTAIS E FRAÇÕES, PORÉM FOI LIBERADO APENAS O RESULTADO DE PROTEINAS TOTAIS. | K6: Arquivo | L6: 07/01/2026 | M6: Unidades de Análises Clínicas | N6: SCIH - Serviço de Controle de Infecção Hospitalar | O6: CLINICA CIRURGICA LEITO 29 | P6: Circunstância de Risco | Q6: Incidente
A7: NÃO HOUVE COLETA DE URINA PARA REALIZAÇÃO DE EXAME | B7: INC 1516 / 2026 | C7: Diretoria Técnica / SCIH - Serviço de Controle de Infecção Hospitalar | D7: Mylena Justino da Silva Brito | E7: Finalizada | F7: 0 | G7: Tiago Soares Fonseca | H7: 05/01/2026 | I7: 05/01/2026 | J7: SOLICITADO EXAME EAS EM 03/01/26. ENTRATANTO ATÉ AS 09:13H DA PRESENTE DATA, O EXAME APARECE COMO "FALTA MATERIAL" NO STATUS DA PLATAFORMA LIS WEB DO LABORATÓRIO DE ANÁLISES CLINICAS. A NÃO REALIZAÇÃO DE EXAMES SOLICITADOS PODE COMPROMETER A ASSISTÊNCIA AO PACIENTE. | K7: Arquivo | L7: 08/01/2026 | M7: Unidade de Internação Cirúrgica | N7: SCIH - Serviço de Controle de Infecção Hospitalar | O7: LEITO 29 | P7: Circunstância de Risco | Q7: Incidente
A8: Falta de registro em prontuário e conduta inadequada de colaborador médico | B8: INC 1517 / 2026 | C8: Gerência de Cuidados Cirúrgicos / Unidade de Internação Cirúrgica | D8: Mylena Justino da Silva Brito | E8: Finalizada | F8: 0 | G8: Debora De Oliveira Alvarenga | H8: 05/01/2026 | I8: 05/01/2026 | J8: Durante plantão assistencial, foram identificadas condutas médicas inadequadas, pelo cirurgião Geral A.M. com repercussão direta na assistência, no fluxo institucional, no dimensionamento da equipe e na segurança do paciente. Avaliação médica realizada por volta das 4h da manhã em paciente vítima de ferimento por arma branca; contudo, a equipe de enfermagem não foi informada da avaliação, e__ não houve registro de evolução médica nem prescrição em prontuário__. __Atraso na definição formal de conduta__, mantendo a equipe de enfermagem sem respaldo técnico para continuidade do cuidado. Comunicação de possível alta de forma verbal a pacientes, sem prescrição ou evolução formal. Recusa ou resistência a avaliações presenciais conforme demanda assistencial. Comunicação inadequada e postura desrespeitosa com a equipe de enfermagem, comprometendo o trabalho multiprofissional. Proferimento de falas indecorosas na sala de prescrição, gerando constrangimento à equipe e quebra do ambiente profissional.__Uso de cigarro eletrônico__ em área assistencial, em desacordo com normas institucionais. | K8: Arquivo | L8: 08/01/2026 | M8: Unidade de Internação Cirúrgica | N8: Unidade de Internação Cirúrgica | O8: LCIR19 | P8: Circunstância de Risco | Q8: Incidente
A9: Falha no registro do horário de recebimento de hemoconcentrado | B9: INC 1518 / 2026 | C9: Gerência de Cuidados Cirúrgicos / Unidade de Internação Cirúrgica | D9: Mylena Justino da Silva Brito | E9: Ignorada | F9: 0 | G9: Debora De Oliveira Alvarenga | H9: 05/01/2026 | I9: 05/01/2026 | J9: Durante verificação de registros assistenciais, foi identificada ausência do horário de recebimento da bolsa de hemoconcentrado. Esse dado é essencial para a rastreabilidade do hemocomponente, controle do tempo de liberação/infusão e segurança do paciente, conforme protocolos institucionais e normas vigentes. Reforça-se a necessidade de atenção ao preenchimento completo e fidedigno dos registros relacionados à hemoterapia. | K9: Arquivo | L9: 07/01/2026 | M9: Unidade de Internação Clínica Médica | N9: Comissões | O9: 15 | P9: Circunstância de Risco | Q9: Incidente
A10: Falha no registro do tipo de hemocomponente | B10: INC 1519 / 2026 | C10: Gerência de Cuidados Cirúrgicos / Unidade de Internação Cirúrgica | D10: Mylena Justino da Silva Brito | E10: Ignorada | F10: 0 | G10: Debora De Oliveira Alvarenga | H10: 05/01/2026 | I10: 05/01/2026 | J10: Durante a verificação dos registros assistenciais, foi identificada a ausência de registro do tipo de hemocomponente administrado. Essa informação é essencial para a rastreabilidade, segurança do paciente e conformidade com os protocolos institucionais e normas de hemoterapia. Reforça-se a obrigatoriedade do preenchimento completo e fidedigno dos registros relacionados à administração de hemocomponentes. | K10: Arquivo | L10: 07/01/2026 | M10: Unidade de Internação Ortopédica | N10: Comissões | O10: 10 | Q10: Incidente
A11: Tempo de transfusão inferior ao preconizado | B11: INC 1520 / 2026 | C11: Gerência de Cuidados Cirúrgicos / Unidade de Internação Cirúrgica | D11: Mylena Justino da Silva Brito | E11: Ignorada | F11: 0 | G11: Debora De Oliveira Alvarenga | H11: 05/01/2026 | I11: 05/01/2026 | J11: Durante a análise dos registros assistenciais, foi identificado tempo de transfusão inferior a 1 hora, em desacordo com os protocolos institucionais e diretrizes de hemoterapia. O cumprimento do tempo adequado de transfusão é fundamental para a segurança do paciente, monitoramento de reações transfusionais e rastreabilidade do processo. Reforça-se a necessidade de adesão aos protocolos e do registro correto das informações relacionadas ao procedimento. | K11: Arquivo | L11: 08/01/2026 | M11: Centro Cirúrgico | N11: Comissões | O11: SALA | Q11: Incidente
A12: Falha no Dimensionamento e Assistência ao Paciente | B12: INC 1521 / 2026 | C12: Gerência de Cuidados Cirúrgicos / Unidade de Internação Cirúrgica | D12: Mylena Justino da Silva Brito | E12: Finalizada | F12: 0 | G12: Debora De Oliveira Alvarenga | H12: 07/01/2026 | I12: 07/01/2026 | J12: Durante o plantão do dia 06/01/2026 sob os cuidados das Enfermeiras Sarah e Antônia, identificou-se que a paciente M.J.D.S leito1 cirúrgica Prontuário 184602, não foi devidamente dimensionada a nenhum técnico de enfermagem. Não houve registro do dimensionamento no livro de ocorrências, tampouco a finalização do referido livro ao término do plantão. Em decorrência dessas falhas, a paciente permaneceu todo o período sem assistência direta da equipe técnica, configurando risco à segurança do paciente e não conformidade com os protocolos assistenciais da instituição. | K12: Arquivo | L12: 07/01/2026 | M12: Unidade de Internação Cirúrgica | N12: Unidade de Internação Cirúrgica | O12: 1 | P12: Circunstância de Risco | Q12: Incidente
A13: Encaminhamento inadequado sem acompanhamento médico de paciente crítico para exame diagnóstico | B13: INC 1522 / 2026 | C13: Gerência Ambulatorial e de Apoio Diagnóstico / Gerência Ambulatorial e de Apoio Diagnóstico | D13: Mylena Justino da Silva Brito | E13: Finalizada | F13: 2 | G13: Nadja Keilane Dantas Espinola | H13: 08/01/2026 | I13: 08/01/2026 | J13: Paciente por volta das proveniente da Sala Vermelha, em estado clínico instável, agitado, sem condições clínicas de colaborar com a realização do exame, sem acompanhamento médico, foi encaminhado ao setor de Tomografia Computadorizada. Durante a permanência no setor, o paciente apresentou vômitos repetidos, mantendo-se agitado e sem estabilidade clínica, o que impossibilitou a realização do exame. Diante da condição apresentada, o exame foi cancelado, e o paciente necessitou retorno imediato ao setor de origem. Ressalta-se que o transporte e a permanência do paciente no setor diagnóstico ocorreram sem a presença de médico assistente, apesar do quadro de instabilidade. RISCOS IDENTIFICADOS AO PACIENTE Risco de broncoaspiração, em razão de vômitos associados à posição supina necessária para o exame de tomografia. Risco de parada cardiorrespiratória, devido ao estado clínico instável e ausência de monitorização contínua. Risco de agravamento do quadro clínico, pela retirada do paciente de ambiente crítico (Sala Vermelha). Risco de trauma físico, decorrente de agitação psicomotora durante tentativa de posicionamento no equipamento. Atraso na assistência adequada, com interrupção de cuidados intensivos necessários. Risco de queda e lesões, pela instabilidade e agitação. Risco infeccioso e ocupacional, pela exposição da equipe a vômitos e secreções em ambiente não preparado para manejo emergencial. IMPLICAÇÕES LEGAIS E NORMATIVAS 1. Segurança do Paciente RDC ANVISA nº 36/2013 Estabelece a obrigatoriedade de práticas assistenciais seguras e da avaliação de risco antes de procedimentos diagnósticos, especialmente em pacientes críticos. 2. Responsabilidade Médica Código de Ética Médica (CFM) É vedado ao médico expor o paciente a risco desnecessário, bem como ausentar-se da assistência a paciente grave sob seus cuidados. Pacientes instáveis devem ser acompanhados por médico durante transporte e exames. 3. Responsabilidade Institucional Encaminhamento inadequado pode caracterizar: Falha no processo assistencial Não conformidade com protocolos de paciente crítico Risco de responsabilização civil da instituição, em caso de dano ao paciente. 4. Boas Práticas em Radiologia Pacientes agitados, instáveis ou com risco clínico elevado não devem ser submetidos a exames de imagem eletivos ou diagnósticos sem estabilização prévia. A realização de exames em pacientes críticos exige: Avaliação médica prévia Condições clínicas adequadas Acompanhamento médico durante todo o procedimento | K13: Arquivo | L13: 08/01/2026 | M13: PS - Pronto Atendimento Adulto | N13: SADT - Unidade de Diagnóstico Por Imagem | O13: TOMOGRAFIA HGP | P13: Circunstância de Risco | Q13: Incidente
A14: LPP SACRAL e CALCÂNEA | B14: INC 1526 / 2026 | C14: Gerência de Cuidados Cirúrgicos / Unidade de Internação Cirúrgica | D14: Mylena Justino da Silva Brito | E14: Finalizada | F14: 0 | G14: Ana Carolina de Oliveira Souza | H14: 08/01/2026 | I14: 08/01/2026 | J14: Lesão por pressão em região sacral e em calcâneo esquerdo, apresentando tecido desvitalizado e risco de infecção associado à pressão prolongada e imobilidade, classificada como Não Estadiável. Realizada avaliação da ferida, limpeza conforme protocolo institucional e curativo com placa de hidrocolóide. Intensificado reposicionamento, ajustada superfície de suporte e orientada equipe quanto ao alívio de pressão. Registro fotográfico realizado. Equipe médica, Equipe de Enfermagem e Comissão de Feridas comunicadas. Segue sem sinais sistêmicos de infecção no momento. Paciente não tolera procedimentos. Está em paliatividade exclusiva. Mantida vigilância diária da evolução da ferida. No prontuário eletrônico há registro em evolução de enfermagem, de início das lesões no mês de novembro (28/11/25), e evolução para grau não estadiável em dezembro (11/12/25). Notifico para registro do caso. | K14: Arquivo | L14: 08/01/2026 | M14: UTI - Unidade de Terapia Intensiva | N14: Comissões | O14: 3 | P14: Evento Adverso Moderado | Q14: Incidente
A15: Medicação suspensa e equipe seguiu com administração | B15: INC 1527 / 2026 | C15: Gerência de Cuidados Materno/Infantil / Unidade de Internação Ginecobstétrica - ALCOM | D15: Mylena Justino da Silva Brito | E15: Finalizada | F15: 1 | G15: Ana Carolina da Costa Frazao Cerqueira | H15: 08/01/2026 | I15: 08/01/2026 | J15: no plantão do dia 06 diurno, o médico suspendeu a medicação "ceftriaxona" da paciente R.S.F.B (333256) para iniciar amoxicilina+ clavulanato, devido a bacteria ser resistente ao ceftriaxona, paciente de isolamento devido tratamento de ITU a enfermeira não cumpriu a meta 2 e nem a meta 3 não identificou na passagem de plantão...a medicação que tinha sido suspensa, continuaram fazendo assumo plantão no dia 07 com as 2 medicaçoes checadas, confirmaram que foram usadas as 2 medicações tanto ceftriaxona como amoxicilina+clavulanato enfermeira do plantão anterior diurno não falou, equipe noturna continuou adm normalmente | K15: Arquivo | L15: 08/01/2026 | M15: Unidade de Internação Gineco Obstétrica | N15: Unidade de Internação Gineco Obstétrica | O15: ISOLAMENTO 2 | P15: Evento sem Dano | Q15: Incidente
A16: Não conformidades nas práticas de Segurança do Paciente - Soro sem identificação | B16: INC 1530 / 2026 | C16: Gerência de Cuidados Cirúrgicos / Unidade de Internação Cirúrgica | D16: Mylena Justino da Silva Brito | E16: Finalizada | F16: 2 | G16: Maria Karoline Miranda Oliveira | H16: 09/01/2026 | I16: 09/01/2026 | J16: Prezados, Venho por meio desta notificar que, na data de hoje as 14h, foi encaminhado ao nosso setor o paciente proveniente do Centro Cirúrgico com soro/medicação em uso sem a devida identificação (nome do paciente, medicamento, concentração e horário). Ressalto que a identificação correta das medicações é uma medida essencial de segurança do paciente, conforme protocolos institucionais e boas práticas assistenciais, sendo indispensável para a continuidade segura do cuidado. Solicitamos, por gentileza, atenção ao cumprimento desse procedimento, a fim de evitar riscos e garantir a qualidade da assistência prestada. | K16: Arquivo | L16: 26/01/2026 | M16: Centro Cirúrgico | N16: Unidade de Internação Cirúrgica | O16: 12 | P16: Circunstância de Risco | Q16: Incidente
A17: CURATIVO NÃO IDENTIFICADO | B17: INC 1531 / 2026 | C17: Gerência de Cuidados Cirúrgicos / Unidade de Internação Cirúrgica | D17: Mylena Justino da Silva Brito | E17: Finalizada | F17: 1 | G17: Ana Carolina de Oliveira Souza | H17: 12/01/2026 | I17: 12/01/2026 | J17: Durante avaliação assistencial, identificado curativo sem identificação, sem data, horário e assinatura do profissional responsável. Situação configura não conformidade assistencial, com potencial impacto na continuidade e segurança do cuidado. Notifico para registro e tratativa. | K17: Arquivo | L17: 27/01/2026 | M17: UTI - Unidade de Terapia Intensiva | N17: Comissões | O17: 1 | P17: Circunstância de Risco | Q17: Incidente
A18: Curativos não identificados | B18: INC 1532 / 2026 | C18: Gerência de Cuidados Cirúrgicos / Unidade de Internação Cirúrgica | D18: Mylena Justino da Silva Brito | E18: Finalizada | F18: 2 | G18: Ana Carolina de Oliveira Souza | H18: 12/01/2026 | I18: 12/01/2026 | J18: Durante avaliação assistencial, identificado 2 curativos sem identificação, sem data, horário e assinatura do profissional responsável. Situação configura não conformidade assistencial, com potencial impacto na continuidade e segurança do cuidado. Notifico para registro e tratativa. | K18: Arquivo | L18: 27/01/2026 | M18: UTI - Unidade de Terapia Intensiva | N18: Comissões | O18: 2 | P18: Circunstância de Risco | Q18: Incidente
A19: CURATIVOS NÃO IDENTIFICADOS | B19: INC 1533 / 2026 | C19: Gerência de Cuidados Cirúrgicos / Unidade de Internação Cirúrgica | D19: Mylena Justino da Silva Brito | E19: Finalizada | F19: 2 | G19: Ana Carolina de Oliveira Souza | H19: 12/01/2026 | I19: 12/01/2026 | J19: Durante avaliação assistencial, identificados 2 curativos sem identificação, sem data, horário e assinatura do profissional responsável. Situação configura não conformidade assistencial, com potencial impacto na continuidade e segurança do cuidado. Notifico para registro e tratativa. | K19: Arquivo | L19: 27/01/2026 | M19: UTI - Unidade de Terapia Intensiva | N19: Comissões | O19: 8 | P19: Circunstância de Risco | Q19: Incidente
A20: Más Condições de higiene e desorganização no leito | B20: INC 1534 / 2026 | C20: Diretoria Geral / Núcleo de Segurança do Paciente | D20: Mylena Justino da Silva Brito | E20: Finalizada | F20: 1 | G20: Talita Andrade Calado da Silva | H20: 12/01/2026 | I20: 12/01/2026 | J20: Durante ronda do núcleo de segurança do paciente, foi identificada más condições de higiene no leito, restos alimentares, roupas sujas e ambiente desorganizado. Segue foto em anexo para melhoria do processo. | K20: Arquivo | L20: 27/01/2026 | M20: PSICO - Unidade de Atenção à Saúde Mental | N20: NSP - Núcleo de Segurança do Paciente | O20: 05 | P20: Circunstância de Risco | Q20: Incidente
A21: Não conformidades nas práticas de Segurança do paciente - Leitos sem identificação beira leito | B21: INC 1535 / 2026 | C21: Diretoria Geral / Núcleo de Segurança do Paciente | D21: Mylena Justino da Silva Brito | E21: Finalizada | F21: 1 | G21: Talita Andrade Calado da Silva | H21: 12/01/2026 | I21: 12/01/2026 | J21: Durante ronda do núcleo de segurança do paciente, foi identificado leitos no ambulatório sem identificado beira leito. segue foto em anexo para ciência. | K21: Arquivo | L21: 27/01/2026 | M21: Unidade Ambulatorial | N21: NSP - Núcleo de Segurança do Paciente | O21: 01 e 02 | P21: Circunstância de Risco | Q21: Incidente
A22: NAO COLETADA URINA PARA REALIZAÇÃO DE EXAME | B22: INC 1536 / 2026 | C22: Diretoria Técnica / SCIH - Serviço de Controle de Infecção Hospitalar | D22: Mylena Justino da Silva Brito | E22: Finalizada | F22: 0 | G22: Tiago Soares Fonseca | H22: 13/01/2026 | I22: 13/01/2026 | J22: EM 12/01/26 SOLICITADO EXAME EAS, POREM, SEGUNDO PLATAFORMA LIS WEB NÃO FOI COLETADA AMOSTRA PARA EXAME. | K22: Arquivo | L22: 27/01/2026 | M22: PS - Pronto Atendimento Adulto | N22: SCIH - Serviço de Controle de Infecção Hospitalar | O22: UDC | P22: Circunstância de Risco | Q22: Incidente
A23: NÃO COLETADA AMOSTRA DE URINA PARA REALIZAÇÃO DE EXAME | B23: INC 1537 / 2026 | C23: Diretoria Técnica / SCIH - Serviço de Controle de Infecção Hospitalar | D23: Mylena Justino da Silva Brito | E23: Finalizada | F23: 0 | G23: Tiago Soares Fonseca | H23: 13/01/2026 | I23: 13/01/2026 | J23: SOLICITADO EAS, PORÉM NÃO FOI COLETADA AMOSTRA. | K23: Arquivo | L23: 27/01/2026 | M23: PS - Pronto Atendimento Adulto | N23: SCIH - Serviço de Controle de Infecção Hospitalar | O23: UDC | P23: Circunstância de Risco | Q23: Incidente
